Workbook
Name Geographies: #REF!

Sheet Main
A1: Table with row headers in column A and column headers in rows 3 through 5.
A2: Look up the code for a specific metro area - select from drop down box
A3: Akron, OH MSA | C3: Code | D3: Index
B4: =+A3 -> Akron, OH MSA | C4: =VLOOKUP($B$4,'Thresholds 2023'!$B$3:$I$379,6,FALSE) -> 0 | D4: =VLOOKUP($B$4,'Thresholds 2023'!$B$3:$I$379,2,FALSE) -> 0.776
A6: Index value from 2018-2022 American Community Survey = | D6: Owner with Mortgage | E6: Owner without a Mortgage | F6: Renter
A7: =+D4 -> 0.776 | C7: National | D7: ='Thresholds 2023'!D2 -> 36915 | E7: ='Thresholds 2023'!E2 -> 30870 | F7: ='Thresholds 2023'!F2 -> 37482
C8: =+A3 -> Akron, OH MSA | D8: =VLOOKUP($B$4,'Thresholds 2023'!$B$3:$I$379,3,FALSE) -> 33326 | E8: =VLOOKUP($B$4,'Thresholds 2023'!$B$3:$I$379,4,FALSE) -> 28636 | F8: =VLOOKUP($B$4,'Thresholds 2023'!$B$3:$I$379,5,FALSE) -> 33763
A33: Internet Release Date: 9/10/2024

Sheet Matrix
A1: Table with row headers in column A and column headers in rows 5 through 9, 30 through 34, 55 through 59. (leading dots indicate subparts)
A2: =+Main!A3 -> Akron, OH MSA | F2: Index Value | G2: =+Main!A7 -> 0.776
A3: Poverty Thresholds for 2023 by Size of Family and Number of Related Children Under 18 Years
A4: Owners with a mortgage
A5: Size of Family Unit | B5: Number of People In Unit | C5: Children under 18 years
C7: None | D7: One | E7: Two | F7: Three | G7: Four | H7: Five | I7: Six | J7: Seven | K7: Eight
D10: 1 | E10: 2 | F10: 3 | G10: 4 | H10: 5 | I10: 6 | J10: 7 | K10: 8
A11: One person (unrelated individual)
A12: .Under 65 years | B12: 1 | C12: =+((1^0.7)/(3^0.7))*$E$20 -> 15445.37
A13: .65 years and over | B13: 1 | C13: =+((1^0.7)/(3^0.7))*$E$20 -> 15445.37
A15: Two people
A16: .Householder under 65 years | B16: 2 | C16: =+($E$20*1.41)/(3^0.7) -> 21777.971 | D16: =+D26 -> 23307.144
A17: .Householder 65 years and over | B17: 2 | C17: =+($E$20*1.41)/(3^0.7) -> 21777.971 | D17: =+D26 -> 23307.144
A18: Two or more Adults
A19: Three people | B19: 3 | C19: =+$E$20*((3^0.7)/3^0.7) -> 33326 | D19: =+(((($B19-D$10)+0.5*D$10)^0.7)/(3^0.7))*$E$20 -> 29332.989
A20: Four people | B20: 4 | C20: =+$E$20*((4^0.7)/3^0.7) -> 40760.575 | D20: =+(((($B20-D$10)+0.5*D$10)^0.7)/(3^0.7))*$E$20 -> 37123.246 | E20: =+Main!D8 -> 33326
A21: Five people | B21: 5 | C21: =+$E$20*((5^0.7)/3^0.7) -> 47651.581 | D21: =+(((($B21-D$10)+0.5*D$10)^0.7)/(3^0.7))*$E$20 -> 44263.635 | E21: =+(((($B21-E$10)+0.5*E$10)^0.7)/(3^0.7))*$E$20 -> 40760.575 | F21: =+(((($B21-F$10)+0.5*F$10)^0.7)/(3^0.7))*$E$20 -> 37123.246
A22: Six people | B22: 6 | C22: =+$E$20*((6^0.7)/3^0.7) -> 54138.247 | D22: =+(((($B22-D$10)+0.5*D$10)^0.7)/(3^0.7))*$E$20 -> 50939.209 | E22: =+(((($B22-E$10)+0.5*E$10)^0.7)/(3^0.7))*$E$20 -> 47651.581 | F22: =+(((($B22-F$10)+0.5*F$10)^0.7)/(3^0.7))*$E$20 -> 44263.635 | G22: =+(((($B22-G$10)+0.5*G$10)^0.7)/(3^0.7))*$E$20 -> 40760.575
A23: Seven people | B23: 7 | C23: =+$E$20*((7^0.7)/3^0.7) -> 60306.891 | D23: =+(((($B23-D$10)+0.5*D$10)^0.7)/(3^0.7))*$E$20 -> 57258.196 | E23: =+(((($B23-E$10)+0.5*E$10)^0.7)/(3^0.7))*$E$20 -> 54138.247 | F23: =+(((($B23-F$10)+0.5*F$10)^0.7)/(3^0.7))*$E$20 -> 50939.209 | G23: =+(((($B23-G$10)+0.5*G$10)^0.7)/(3^0.7))*$E$20 -> 47651.581 | H23: =+(((($B23-H$10)+0.5*H$10)^0.7)/(3^0.7))*$E$20 -> 44263.635
A24: Eight people | B24: 8 | C24: =+$E$20*((8^0.7)/3^0.7) -> 66215.75 | D24: =+(((($B24-D$10)+0.5*D$10)^0.7)/(3^0.7))*$E$20 -> 63290.889 | E24: =+(((($B24-E$10)+0.5*E$10)^0.7)/(3^0.7))*$E$20 -> 60306.891 | F24: =+(((($B24-F$10)+0.5*F$10)^0.7)/(3^0.7))*$E$20 -> 57258.196 | G24: =+(((($B24-G$10)+0.5*G$10)^0.7)/(3^0.7))*$E$20 -> 54138.247 | H24: =+(((($B24-H$10)+0.5*H$10)^0.7)/(3^0.7))*$E$20 -> 50939.209 | I24: =+(((($B24-I$10)+0.5*I$10)^0.7)/(3^0.7))*$E$20 -> 47651.581
A25: One Adult with Child/Children
A26: Single Parent | D26: =+((1.8^0.7)/(3^0.7))*$E$20 -> 23307.144 | E26: =+(((1.8+0.5*(E$10-1))^0.7)/(3^0.7))*$E$20 -> 27669.913 | F26: =+(((1.8+0.5*(F$10-1))^0.7)/(3^0.7))*$E$20 -> 31754.767 | G26: =+(((1.8+0.5*(G$10-1))^0.7)/(3^0.7))*$E$20 -> 35625.262 | H26: =+(((1.8+0.5*(H$10-1))^0.7)/(3^0.7))*$E$20 -> 39323.017 | I26: =+(((1.8+0.5*(I$10-1))^0.7)/(3^0.7))*$E$20 -> 42877.182 | J26: =+(((1.8+0.5*(J$10-1))^0.7)/(3^0.7))*$E$20 -> 46309.189 | K26: =+(((1.8+0.5*(K$10-1))^0.7)/(3^0.7))*$E$20 -> 49635.388
A28: Source: U.S. Census Bureau.
A29: Owners without a mortgage
A30: Size of Family Unit | B30: Number of People In Unit | C30: Children under 18 years
C32: None | D32: One | E32: Two | F32: Three | G32: Four | H32: Five | I32: Six | J32: Seven | K32: Eight
D35: 1 | E35: 2 | F35: 3 | G35: 4 | H35: 5 | I35: 6 | J35: 7 | K35: 8
A36: One person (unrelated individual)
A37: .Under 65 years | B37: 1 | C37: =+((1^0.7)/(3^0.7))*$E$45 -> 13271.728
A38: .65 years and over | B38: 1 | C38: =+((1^0.7)/(3^0.7))*$E$45 -> 13271.728
A40: Two people
A41: .Householder under 65 years | B41: 2 | C41: =+($E$45*1.41)/(3^0.7) -> 18713.137 | D41: =+D51 -> 20027.108
A42: .Householder 65 years and over | B42: 2 | C42: =+($E$45*1.41)/(3^0.7) -> 18713.137 | D42: =+D51 -> 20027.108
A43: Two or more Adults
A44: Three people | B44: 3 | C44: =+$E$45*((3^0.7)/3^0.7) -> 28636 | D44: =+(((($B44-D$10)+0.5*D$10)^0.7)/(3^0.7))*$E$45 -> 25204.929
A45: Four people | B45: 4 | C45: =+$E$45*((4^0.7)/3^0.7) -> 35024.3 | D45: =+(((($B45-D$10)+0.5*D$10)^0.7)/(3^0.7))*$E$45 -> 31898.856 | E45: =+Main!E8 -> 28636
A46: Five people | B46: 5 | C46: =+$E$45*((5^0.7)/3^0.7) -> 40945.528 | D46: =+(((($B46-D$10)+0.5*D$10)^0.7)/(3^0.7))*$E$45 -> 38034.371 | E46: =+(((($B46-E$10)+0.5*E$10)^0.7)/(3^0.7))*$E$45 -> 35024.3 | F46: =+(((($B46-F$10)+0.5*F$10)^0.7)/(3^0.7))*$E$45 -> 31898.856
A47: Six people | B47: 6 | C47: =+$E$45*((6^0.7)/3^0.7) -> 46519.319 | D47: =+(((($B47-D$10)+0.5*D$10)^0.7)/(3^0.7))*$E$45 -> 43770.485 | E47: =+(((($B47-E$10)+0.5*E$10)^0.7)/(3^0.7))*$E$45 -> 40945.528 | F47: =+(((($B47-F$10)+0.5*F$10)^0.7)/(3^0.7))*$E$45 -> 38034.371 | G47: =+(((($B47-G$10)+0.5*G$10)^0.7)/(3^0.7))*$E$45 -> 35024.3
A48: Seven people | B48: 7 | C48: =+$E$45*((7^0.7)/3^0.7) -> 51819.844 | D48: =+(((($B48-D$10)+0.5*D$10)^0.7)/(3^0.7))*$E$45 -> 49200.195 | E48: =+(((($B48-E$10)+0.5*E$10)^0.7)/(3^0.7))*$E$45 -> 46519.319 | F48: =+(((($B48-F$10)+0.5*F$10)^0.7)/(3^0.7))*$E$45 -> 43770.485 | G48: =+(((($B48-G$10)+0.5*G$10)^0.7)/(3^0.7))*$E$45 -> 40945.528 | H48: =+(((($B48-H$10)+0.5*H$10)^0.7)/(3^0.7))*$E$45 -> 38034.371
A49: Eight people | B49: 8 | C49: =+$E$45*((8^0.7)/3^0.7) -> 56897.144 | D49: =+(((($B49-D$10)+0.5*D$10)^0.7)/(3^0.7))*$E$45 -> 54383.901 | E49: =+(((($B49-E$10)+0.5*E$10)^0.7)/(3^0.7))*$E$45 -> 51819.844 | F49: =+(((($B49-F$10)+0.5*F$10)^0.7)/(3^0.7))*$E$45 -> 49200.195 | G49: =+(((($B49-G$10)+0.5*G$10)^0.7)/(3^0.7))*$E$45 -> 46519.319 | H49: =+(((($B49-H$10)+0.5*H$10)^0.7)/(3^0.7))*$E$45 -> 43770.485 | I49: =+(((($B49-I$10)+0.5*I$10)^0.7)/(3^0.7))*$E$45 -> 40945.528
...

Sheet Thresholds 2023
A1: Table 2. Thresholds for Two Adult Two Child Families: 2023 | C1: Index based on Median Rents | D1: Homeowners with Mortgage | E1: Homeowners without a Mortgage | F1: Renters
B2: Thresholds from Bureau of Labor Statistics* | D2: 36915 | E2: 30870 | F2: 37482
A3: 1002 | B3: Alabama Nonmetro | C3: 0.565 | D3: =ROUND((+$C3*D$2*0.434+(1-0.434)*D$2),0) -> 29946 | E3: =ROUND((+$C3*E$2*0.323+(1-0.323)*E$2),0) -> 26533 | F3: =ROUND((+$C3*F$2*0.443+(1-0.443)*F$2),0) -> 30259
A4: 2001 | B4: Alaska Metro | C4: 1.085 | D4: =ROUND((+$C4*D$2*0.434+(1-0.434)*D$2),0) -> 38277 | E4: =ROUND((+$C4*E$2*0.323+(1-0.323)*E$2),0) -> 31718 | F4: =ROUND((+$C4*F$2*0.443+(1-0.443)*F$2),0) -> 38893
A5: 2002 | B5: Alaska Nonmetro | C5: 1.071 | D5: =ROUND((+$C5*D$2*0.434+(1-0.434)*D$2),0) -> 38052 | E5: =ROUND((+$C5*E$2*0.323+(1-0.323)*E$2),0) -> 31578 | F5: =ROUND((+$C5*F$2*0.443+(1-0.443)*F$2),0) -> 38661
A6: 4001 | B6: Arizona Metro | C6: 1.089 | D6: =ROUND((+$C6*D$2*0.434+(1-0.434)*D$2),0) -> 38341 | E6: =ROUND((+$C6*E$2*0.323+(1-0.323)*E$2),0) -> 31757 | F6: =ROUND((+$C6*F$2*0.443+(1-0.443)*F$2),0) -> 38960
A7: 4002 | B7: Arizona Nonmetro | C7: 0.588 | D7: =ROUND((+$C7*D$2*0.434+(1-0.434)*D$2),0) -> 30314 | E7: =ROUND((+$C7*E$2*0.323+(1-0.323)*E$2),0) -> 26762 | F7: =ROUND((+$C7*F$2*0.443+(1-0.443)*F$2),0) -> 30641
A8: 5001 | B8: Arkansas Metro | C8: 0.677 | D8: =ROUND((+$C8*D$2*0.434+(1-0.434)*D$2),0) -> 31740 | E8: =ROUND((+$C8*E$2*0.323+(1-0.323)*E$2),0) -> 27649 | F8: =ROUND((+$C8*F$2*0.443+(1-0.443)*F$2),0) -> 32119
A9: 5002 | B9: Arkansas Nonmetro | C9: 0.594 | D9: =ROUND((+$C9*D$2*0.434+(1-0.434)*D$2),0) -> 30410 | E9: =ROUND((+$C9*E$2*0.323+(1-0.323)*E$2),0) -> 26822 | F9: =ROUND((+$C9*F$2*0.443+(1-0.443)*F$2),0) -> 30741
A10: 6002 | B10: California Nonmetro | C10: 0.959 | D10: =ROUND((+$C10*D$2*0.434+(1-0.434)*D$2),0) -> 36258 | E10: =ROUND((+$C10*E$2*0.323+(1-0.323)*E$2),0) -> 30461 | F10: =ROUND((+$C10*F$2*0.443+(1-0.443)*F$2),0) -> 36801
A11: 8002 | B11: Colorado Nonmetro | C11: 0.897 | D11: =ROUND((+$C11*D$2*0.434+(1-0.434)*D$2),0) -> 35265 | E11: =ROUND((+$C11*E$2*0.323+(1-0.323)*E$2),0) -> 29843 | F11: =ROUND((+$C11*F$2*0.443+(1-0.443)*F$2),0) -> 35772
A12: 9002 | B12: Connecticut Nonmetro | C12: 0.989 | D12: =ROUND((+$C12*D$2*0.434+(1-0.434)*D$2),0) -> 36739 | E12: =ROUND((+$C12*E$2*0.323+(1-0.323)*E$2),0) -> 30760 | F12: =ROUND((+$C12*F$2*0.443+(1-0.443)*F$2),0) -> 37299
A13: 10180 | B13: Abilene, TX MSA | C13: 0.845 | D13: =ROUND((+$C13*D$2*0.434+(1-0.434)*D$2),0) -> 34432 | E13: =ROUND((+$C13*E$2*0.323+(1-0.323)*E$2),0) -> 29324 | F13: =ROUND((+$C13*F$2*0.443+(1-0.443)*F$2),0) -> 34908
A14: 10420 | B14: Akron, OH MSA | C14: 0.776 | D14: =ROUND((+$C14*D$2*0.434+(1-0.434)*D$2),0) -> 33326 | E14: =ROUND((+$C14*E$2*0.323+(1-0.323)*E$2),0) -> 28636 | F14: =ROUND((+$C14*F$2*0.443+(1-0.443)*F$2),0) -> 33763
... A343: 56002 | B343: Wyoming Nonmetro | C343: 0.692 | D343: =ROUND((+$C343*D$2*0.434+(1-0.434)*D$2),0) -> 31980 | E343: =ROUND((+$C343*E$2*0.323+(1-0.323)*E$2),0) -> 27799 | F343: =ROUND((+$C343*F$2*0.443+(1-0.443)*F$2),0) -> 32368
A344: Source: The 2023 Supplemental Poverty Measure (SPM) thresholds were produced by Ryan M. Unitan in the Division of Price and Index Number Research, Bureau of Labor Statistics (BLS). The thresholds and standard errors are based on data from the U.S. Consumer Expenditure Survey (CE) Interview, with all data consumer unit weighted. Standard errors of the thresholds are derived using replicate weights available in the CE Interview data files. Information regarding the estimation of standard errors based on CE replicate weights is available at <https://www.bls.gov/cex/pumd-getting-started-guide.htm>. Thresholds and standards error are produced as a BLS research series and are not considered an official production series. Methodological details and related research regarding the SPM thresholds are available at <https://stats.bls.gov/pir/spmhome.htm>. The 2023 thresholds and related statistics were finalized as of May 13, 2024 and include the imputed value of broadband subsidy benefits. The thresholds for 2022 were finalized as of May 11, 2023.
